I'm sorry, but an uncaught exception occurred.

While running game code:
  File "game/script2.rpy", line 204, in script
    sir_hendrick " 'Your assistance is crucial. The empire seldom responds to our requests for assistance, but their yearly supply delivery was supposed to arrive two weeks ago. Our last confirmation that the supply train was safe was the village before Greenfield– something must have happened to the wagon train on its way to or in Greenfield. We’ll need you to go investigate so that we can find the supplies we desperately need, but the path is overrun with dangers. You'll need to be cautious and swift.'"
Exception: Sayer 'sir_hendrick' is not defined.

-- Full Traceback ------------------------------------------------------------

Full traceback:
  File "game/script2.rpy", line 204, in script
    sir_hendrick " 'Your assistance is crucial. The empire seldom responds to our requests for assistance, but their yearly supply delivery was supposed to arrive two weeks ago. Our last confirmation that the supply train was safe was the village before Greenfield– something must have happened to the wagon train on its way to or in Greenfield. We’ll need you to go investigate so that we can find the supplies we desperately need, but the path is overrun with dangers. You'll need to be cautious and swift.'"
  File "C:\Users\lucav\OneDrive\Documents\GitHub\Fragmented\renpy-8.1.3-sdk\renpy\ast.py", line 890, in execute
    who = eval_who(self.who, self.who_fast)
  File "C:\Users\lucav\OneDrive\Documents\GitHub\Fragmented\renpy-8.1.3-sdk\renpy\ast.py", line 783, in eval_who
    raise Exception("Sayer '%s' is not defined." % who)
Exception: Sayer 'sir_hendrick' is not defined.

Windows-10-10.0.22621 AMD64
Ren'Py 8.1.3.23091805
Fragmented 1.0
Wed Nov 15 20:28:37 2023
